Workbook

Sheet Início
A1: Playbook Comercial LedWave · versão resumida
A2: Vender primeiro a LedWave, depois o porquê do cliente · apresentações de 10 a 20 min · v3 (out/2026)
A4: Como usar em 5 passos
A5: 1. Antes da reunião | B5: Aba Descoberta: perguntas SPIN e o que levantar para orçar o nicho.
A6: 2. Monte o roteiro | B6: Aba Gerador: escolha nicho e duração; o roteiro sai pronto em 7 blocos.
A7: 3. Descubra o propósito | B7: Aba Mapa de Venda: identifique por que este cliente compra (mídia, branding, experiência...) e use os diferenciais, resultados e cases daquele propósito.
A8: 4. Trate as objeções | B8: Aba Objeções: resposta curta + a prova que você leva.
A9: 5. Contribua | B9: Aba Ideias: uma linha por ideia. As aprovadas sobem para a matriz Nichos.
A11: LedWave em 1 minuto (usado no bloco 3 do Gerador)
A12: Prova | B12: Como falar | C12: Fonte | D12: Status | E12: Observação
A13: Origem | B13: Começamos com R$ 12 mil e uma ideia trazida de Xangai. Hoje somos referência em LED no Brasil. | C13: Exame | D13: OK
A14: Liderança | B14: Quatro anos seguidos entre as empresas que mais crescem no Brasil e nº 1 do segmento de painéis de LED no ranking Exame 2025. | C14: Ranking Exame Negócios em Expansão | D14: OK
A15: Projeto-ícone | B15: Fizemos o Boulevard.Live: 1.125 m², o maior painel de LED da América Latina. | C15: Blog LedWave; Inviron | D15: OK
A16: Presença | B16: Fábrica em Goiânia e unidades em São Paulo, Brasília e Orlando (EUA). | C16: Site LedWave | D16: OK
A17: Internacional | B17: Única empresa brasileira de LED com estande próprio na NRF 2026, em Nova York. | C17: Imprensa | D17: OK
A18: Clientes | B18: Nordestão, Rosewood, Beto Carrero World e Museu do Amanhã escolheram a LedWave. | C18: Time comercial | D18: Confirmar autorização
A20: Legenda
A21: Campo para preencher
A22: Versão completa (roleplay, técnicas, frases, prospecção detalhada): arquivo LedWave_Playbook_Comercial_Nichos.xlsx

Sheet Gerador
A1: Gerador de Roteiro
A2: Escolha nicho e duração nas células amarelas. Ajuste os percentuais da coluna B se quiser (devem somar 100%).
A4: Nicho | B4: Supermercados, Atacarejos e Home Centers | F4: =IFERROR("Decisor: "&INDEX(Nichos!$B:$B,MATCH($B$4,Nichos!$A:$A,0))&" · Propósitos de compra: "&INDEX(Nichos!$C:$C,MATCH($B$4,Nichos!$A:$A,0)),"Escolha um nicho da lista") -> Decisor: Diretor Comercial, Diretor de Trade Marketing, Gerente de Marketing, Operações · Propósitos de compra: Retail media · Trade · Eficiência operacional
A5: Duração (min) | B5: 15
A7: Bloco | B7: % do tempo | C7: Minutos | D7: Termina em | E7: Técnica | F7: Fala do nicho
A8: 1. Abertura: pergunta | B8: 0.08 | C8: =B8*$B$5 -> 1.2 | D8: =SUM($C$8:C8) -> 1.2 | E8: Pergunta provocativa + pausa de 3 s | F8: =IFERROR("PERGUNTE: "&INDEX(Nichos!$E:$E,MATCH($B$4,Nichos!$A:$A,0)),"Escolha um nicho da lista") -> PERGUNTE: Se 80% a 90% das vendas do varejo ainda acontecem na loja física, por que quase toda a verba de mídia está fora dela?
A9: 2. Dor e custo de esperar | B9: 0.2 | C9: =B9*$B$5 -> 3 | D9: =SUM($C$8:C9) -> 4.2 | E9: SPIN + escuta 70/30 | F9: =IFERROR(INDEX(Nichos!$D:$D,MATCH($B$4,Nichos!$A:$A,0))&CHAR(10)&"SITUAÇÃO: "&INDEX(Descoberta!$B:$B,MATCH($B$4,Descoberta!$A:$A,0))&CHAR(10)&"PROBLEMA: "&INDEX(Descoberta!$C:$C,MATCH($B$4,Descoberta!$A:$A,0))&CHAR(10)&"IMPLICAÇÃO: "&INDEX(Descoberta!$D:$D,MATCH($B$4,Descoberta!$A:$A,0)),"Escolha um nicho da lista") -> Oferta muda todo dia, cartaz de papel não acompanha. O trade da indústria paga por espaço, mas o impresso não mede nada e envelhece rápido. Custo de esperar: O varejista deixa de vender mídia dentro da própria loja, enquanto o retail media cresce no Brasil (R$ 4,8 bi em 2025, +37%, IAB Brasil/Kantar). SITUAÇÃO: Quantas lojas e checkouts? Como as ofertas são comunicadas hoje? A indústria investe em trade nas suas lojas? PROBLEMA: Quanto tempo leva para uma oferta sair do comercial e chegar à gôndola? O fornecedor pede comprovação de exposição? IMPLICAÇÃO: Quanto de verba de trade vira papel que ninguém mede? Quanto você deixa de faturar por não vender mídia dentro da loja?
A10: 3. LedWave: o guia | B10: 0.18 | C10: =B10*$B$5 -> 2.7 | D10: =SUM($C$8:C10) -> 6.9 | E10: StoryBrand + regra de 3 | F10: =IFERROR(INDEX(Início!$B:$B,13)&CHAR(10)&INDEX(Início!$B:$B,14)&CHAR(10)&INDEX(Início!$B:$B,15)&CHAR(10)&"CASE: "&IF(INDEX(Nichos!$J:$J,MATCH($B$4,Nichos!$A:$A,0))="","Boulevard.Live",INDEX(Nichos!$J:$J,MATCH($B$4,Nichos!$A:$A,0)))&CHAR(10)&"Ponte: E é por isso que estamos aqui.","Escolha um nicho da lista") -> Começamos com R$ 12 mil e uma ideia trazida de Xangai. Hoje somos referência em LED no Brasil. Quatro anos seguidos entre as empresas que mais crescem no Brasil e nº 1 do segmento de painéis de LED no ranking Exame 2025. Fizemos o Boulevard.Live: 1.125 m², o maior painel de LED da América Latina. CASE: Nordestão Ponte: E é por isso que estamos aqui.
A11: 4. O porquê | B11: 0.12 | C11: =B11*$B$5 -> 1.8 | D11: =SUM($C$8:C11) -> 8.7 | E11: Golden Circle + analogia | F11: =IFERROR("CONFIRME O PROPÓSITO DE COMPRA ("&INDEX(Nichos!$C:$C,MATCH($B$4,Nichos!$A:$A,0))&") e use a aba Mapa de Venda."&CHAR(10)&INDEX(Nichos!$F:$F,MATCH($B$4,Nichos!$A:$A,0))&CHAR(10)&"FRASE (pausa): "&INDEX(Nichos!$H:$H,MATCH($B$4,Nichos!$A:$A,0)),"Escolha um nicho da lista") -> CONFIRME O PROPÓSITO DE COMPRA (Retail media · Trade · Eficiência operacional) e use a aba Mapa de Venda. Transformar a loja em canal de mídia: a tela deixa de ser custo e passa a gerar receita com as marcas que já estão nas gôndolas. História: Referência Walmart Connect: a loja virou canal de mídia e a publicidade virou uma linha de receita bilionária. A lição é simples: a loja física também é mídia, e mídia gera receita. FRASE (pausa): Sua loja já tem audiência. Falta transformar audiência em receita.
A12: 5. Três ganhos e solução | B12: 0.2 | C12: =B12*$B$5 -> 3 | D12: =SUM($C$8:C12) -> 11.7 | E12: Regra de 3 + antes/depois | F12: =IFERROR(INDEX(Nichos!$G:$G,MATCH($B$4,Nichos!$A:$A,0))&CHAR(10)&"SOLUÇÃO E KPIs: "&INDEX(Nichos!$I:$I,MATCH($B$4,Nichos!$A:$A,0)),"Escolha um nicho da lista") -> Receita: Retail media: venda de espaço nas telas para a indústria, com margem potencial de 70% a 90% (McKinsey). A tela se paga com a verba de trade. Experiência: Ofertas e receitas em movimento no momento da decisão; comunicação mais moderna que a da concorrência no mesmo bairro. Operação: Troca de preços e ofertas em tempo real por loja, sem impressão, sem retrabalho, com prova de veiculação para o fornecedor. SOLUÇÃO E KPIs: Telas de checkout, ponta de gôndola, painéis de entrada e fachada, retail media com gestão de conteúdo e relatório de veiculação (parceria WeOOH a validar). KPIs: Receita de mídia por loja, sell-out do produto anunciado, economia com impressos, tempo de troca de oferta.
A13: 6. Objeções antecipadas | B13: 0.1 | C13: =B13*$B$5 -> 1.5 | D13: =SUM($C$8:C13) -> 13.2 | E13: Ouvir, acolher, explorar, responder com prova | F13: =IFERROR("MAIS PROVÁVEIS: "&INDEX(Nichos!$K:$K,MATCH($B$4,Nichos!$A:$A,0))&" (respostas na aba Objeções)","Escolha um nicho da lista") -> MAIS PROVÁVEIS: Gestão de conteúdo; Aprovação por financeiro; Momento financeiro (respostas na aba Objeções)
A14: 7. Fechamento | B14: 0.12 | C14: =B14*$B$5 -> 1.8 | D14: =SUM($C$8:C14) -> 15 | E14: Peak-End + escolha entre duas datas | F14: =IFERROR("NECESSIDADE: "&INDEX(Descoberta!$E:$E,MATCH($B$4,Descoberta!$A:$A,0))&CHAR(10)&"FRASE: "&INDEX(Nichos!$H:$H,MATCH($B$4,Nichos!$A:$A,0))&CHAR(10)&INDEX(Nichos!$L:$L,MATCH($B$4,Nichos!$A:$A,0)),"Escolha um nicho da lista") -> NECESSIDADE: Se as telas fossem pagas pela indústria e ainda gerassem receita, quantas lojas você colocaria no piloto? FRASE: Sua loja já tem audiência. Falta transformar audiência em receita. A pergunta não é se o seu PDV vai virar mídia. É quem vai fazer isso primeiro na sua praça. Próximo passo: Workshop de 1h para desenhar o piloto de retail media em 1 a 3 lojas.
A15: Total | B15: =SUM(B8:B14) -> 1 | C15: =SUM(C8:C14) -> 15 | E15: =IF(ROUND(B15,2)=1,"OK","Ajuste para somar 100%") -> OK

Sheet Nichos
A1: Nichos: o porquê de cada cliente
A2: Uma linha por nicho, fonte do Gerador. Mantenha a ordem das colunas; melhore os textos à vontade.
A3: Nicho | B3: Decisor típico | C3: Propósitos de compra | D3: Dor e custo de esperar | E3: Pergunta de abertura | F3: O porquê + história | G3: Três ganhos | H3: Frase de efeito | I3: Solução e KPIs | J3: Cases | K3: Objeções prováveis | L3: Fechamento e próximo passo | M3: Ideias no banco
A4: Varejo de Moda e Vitrines | B4: Dono da rede, Diretor de Marketing, Gerente de Visual Merchandising | C4: Branding · Experiência · Trade | D4: A vitrine é estática: a coleção muda, a promoção muda, mas a fachada fala a mesma coisa por semanas. Cada troca exige gráfica, instalação e prazo. Custo de esperar: Cada dia com vitrine parada é fluxo de calçada que passa reto. Quem não para na vitrine não entra na loja. | E4: Quantas pessoas passam na frente da sua loja por dia? Agora, quantas param? A diferença entre esses dois números é o tamanho da oportunidade que estamos aqui para discutir. | F4: Transformar a vitrine em um vendedor que trabalha 24h, chama o cliente pelo movimento e conta a história da coleção antes de ele entrar. História: Antes x depois: a mesma vitrine com um banner de liquidação desbotado e, ao lado, a coleção nova em movimento, com troca de conteúdo do celular em minutos. O olho humano é programado para seguir movimento. | G4: Receita: Mais paradas na vitrine geram mais entradas na loja; promoções relâmpago (horário de almoço, fim de tarde) entram no ar na hora, sem gráfica. Experiência: A marca passa a ter cara de flagship: a loja de rua ou de shopping conversa com o padrão das grandes marcas internacionais. Operação: Fim do custo recorrente de impressão e instalação a cada coleção; gestão centralizada do conteúdo para todas as lojas da rede. | H4: Vitrine parada é vendedor dormindo. | I4: Painel de vitrine de alto brilho, LED transparente para fachadas de vidro, totens digitais internos, gestão de conteúdo em rede. KPIs: Taxa de parada na vitrine, entrada em loja, vendas da peça anunciada, economia com impressos. | K4: Preço; Gestão de conteúdo; Percepção de valor | L4: A coleção nova merece uma vitrine à altura. Vamos colocar a sua loja para falar com quem passa? Próximo passo: Agendar visita técnica para medir a vitrine e simular o conteúdo da próxima coleção no painel. | M4: =COUNTIF(Ideias!$C:$C,A4) -> 0
A5: Supermercados, Atacarejos e Home Centers | B5: Diretor Comercial, Diretor de Trade Marketing, Gerente de Marketing, Operações | C5: Retail media · Trade · Eficiência operacional | D5: Oferta muda todo dia, cartaz de papel não acompanha. O trade da indústria paga por espaço, mas o impresso não mede nada e envelhece rápido. Custo de esperar: O varejista deixa de vender mídia dentro da própria loja, enquanto o retail media cresce no Brasil (R$ 4,8 bi em 2025, +37%, IAB Brasil/Kantar). | E5: Se 80% a 90% das vendas do varejo ainda acontecem na loja física, por que quase toda a verba de mídia está fora dela? | F5: Transformar a loja em canal de mídia: a tela deixa de ser custo e passa a gerar receita com as marcas que já estão nas gôndolas. História: Referência Walmart Connect: a loja virou canal de mídia e a publicidade virou uma linha de receita bilionária. A lição é simples: a loja física também é mídia, e mídia gera receita. | G5: Receita: Retail media: venda de espaço nas telas para a indústria, com margem potencial de 70% a 90% (McKinsey). A tela se paga com a verba de trade. Experiência: Ofertas e receitas em movimento no momento da decisão; comunicação mais moderna que a da concorrência no mesmo bairro. Operação: Troca de preços e ofertas em tempo real por loja, sem impressão, sem retrabalho, com prova de veiculação para o fornecedor. | H5: Sua loja já tem audiência. Falta transformar audiência em receita. | I5: Telas de checkout, ponta de gôndola, painéis de entrada e fachada, retail media com gestão de conteúdo e relatório de veiculação (parceria WeOOH a validar). KPIs: Receita de mídia por loja, sell-out do produto anunciado, economia com impressos, tempo de troca de oferta. | J5: Nordestão | K5: Gestão de conteúdo; Aprovação por financeiro; Momento financeiro | L5: A pergunta não é se o seu PDV vai virar mídia. É quem vai fazer isso primeiro na sua praça. Próximo passo: Workshop de 1h para desenhar o piloto de retail media em 1 a 3 lojas. | M5: =COUNTIF(Ideias!$C:$C,A5) -> 0
A6: Farmácias e Drogarias | B6: Diretor de Marketing, Diretor de Expansão, Dono da rede, Trade | C6: Retail media · Trade · Branding | D6: Fachadas parecidas, guerra de preço e um corredor cheio de marcas disputando atenção. A indústria farmacêutica e de dermocosméticos quer visibilidade, mas o espaço é pequeno. Custo de esperar: A farmácia da esquina igual a todas as outras perde a decisão de entrada para a que se destaca, e deixa de monetizar o espaço com a indústria. | E6: Na sua rua existem quantas farmácias? O que faz o cliente escolher a sua antes de ver o preço? | F6: Fazer da farmácia um ponto de saúde e bem-estar que se vê de longe e informa de perto, com mídia paga pela indústria. História: Cruz verde iluminada foi a primeira tela da farmácia. O painel de LED é a evolução natural dessa cruz: além de dizer 'estou aqui', diz 'tenho o que você precisa hoje'. | G6: Receita: Monetização com a indústria (dermocosméticos, OTC, higiene) em telas internas; campanhas sazonais (gripe, verão, Dia das Mães) entram no ar na hora. Experiência: Fachada que se destaca na rua, conteúdo de saúde e prevenção que gera confiança, fila mais leve com conteúdo útil. Operação: Padronização da comunicação em todas as lojas da rede a partir de um único painel de controle. | H6: Farmácia que se vê de longe vende antes do preço. | I6: Painel de fachada, LED de vitrine, telas atrás do balcão e na área de dermocosméticos, rede de retail media. KPIs: Receita de mídia com a indústria, vendas de categorias anunciadas, fluxo de entrada, tempo de rollout de campanha. | K6: Política comercial; Gestão de conteúdo; Percepção de valor | L6: A cruz verde chamou o cliente por décadas. Agora é hora de ela conversar com ele. Próximo passo: Simulação de fachada digital com a identidade da rede + proposta de piloto em uma loja âncora. | M6: =COUNTIF(Ideias!$C:$C,A6) -> 1
A7: Postos de Combustível e Conveniência | B7: Proprietário do posto/rede, Diretor Comercial de distribuidora, Gerente de conveniência | C7: Mídia · Eficiência operacional · Branding | D7: O preço na placa é a única comunicação, e o cliente decide em segundos, a 60 km/h. A loja de conveniência é invisível da pista. Custo de esperar: O motorista que passa reto não volta. A margem do combustível é apertada e a conveniência, que tem margem, não é vista. | E7: Seu cliente decide se entra no seu posto em menos de cinco segundos. O que ele vê nesses cinco segundos? | F7: Fazer o posto ser visto, escolhido e lembrado, e transformar a rodovia em audiência paga. História: Duas placas na estrada à noite: uma de preço fixo, apagada; outra com preço, promoção de café + pão de queijo e a marca em movimento. Qual delas faz o motorista dar seta? | G7: Receita: Mídia DOOH para anunciantes locais e regionais na pista; promoções da conveniência e serviços (lavagem, troca de óleo) que aumentam ticket. Experiência: Posto moderno, iluminado e seguro à noite, percepção de marca forte na rodovia. Operação: Atualização de preço remota e instantânea, sem subir em escada, com conteúdo programado por horário. | H7: Na estrada, quem não é visto não é abastecido. | I7: Totem de preços em LED outdoor (alto brilho, IP65), painel de testeira, telas na bomba e na conveniência, mídia DOOH. KPIs: Veículos que entram x fluxo da pista, ticket da conveniência, receita de mídia DOOH. | K7: Política local / licenças; Fabricação de estrutura metálica; Consumo de energia | L7: Seu posto já tem o fluxo. Vamos fazer esse fluxo parar? Próximo passo: Estudo de visibilidade da pista (distância, ângulo, fluxo) e proposta de totem + testeira. | M7: =COUNTIF(Ideias!$C:$C,A7) -> 0
A8: DOOH e Investidores de Mídia | B8: Investidor, CEO/Proprietário de exibidora, Diretor Comercial de mídia | C8: Mídia · Status · Retrofit / arquitetura | D8: Quer entrar ou crescer em mídia exterior digital, mas precisa de ativo confiável, ponto bem escolhido e retorno previsível. Custo de esperar: Os melhores pontos da cidade estão sendo ocupados agora. Ponto bom não espera. | E8: Um painel de LED não é um custo, é um imóvel que paga aluguel em inserções. A pergunta é: quanto rende o seu metro quadrado? | F8: Construir um ativo de mídia que gera receita recorrente por anos, com um fabricante que sabe operar mídia porque também opera. História: Boulevard.Live, em Brasília: 1.125 m², o maior painel de LED da América Latina, pensado no ponto de maior fluxo de pessoas e veículos da cidade. A LedWave não só vende painel; ela sabe o que faz um painel faturar. | G8: Receita: Receita recorrente por inserção, programática e anunciante local; o DOOH já soma R$ 4,4 bi no Brasil (IAB Brasil/Kantar, 2025). Experiência: Ponto icônico vira referência da cidade e atrai anunciantes premium. Operação: Fabricação própria, assistência técnica, alto brilho e durabilidade outdoor reduzem tempo de tela apagada (que é receita perdida). | H8: Painel apagado é aluguel perdido. Escolha quem mantém sua tela no ar. | I8: Painéis outdoor de grande formato, empenas, frontlights digitais, mobiliário urbano, gestão de conteúdo e programação. KPIs: Ocupação, receita por m², uptime da tela, payback do ponto. | K8: Política local / licenças; SLA; Crédito | L8: Vamos escolher juntos o seu próximo ponto e colocar a conta no papel? Próximo passo: Estudo de ponto + simulação de payback com cenário conservador, base e otimista. | M8: =COUNTIF(Ideias!$C:$C,A8) -> 0
A9: Shopping Centers | B9: Superintendente, Gerente de Marketing, Gerente Comercial / Mall & Media | C9: Experiência · Entretenimento · Mídia | D9: O shopping disputa visita com o e-commerce e precisa ser destino. O mall media tradicional é estático e difícil de vender. Custo de esperar: Sem experiência, o shopping vira corredor de passagem; e o espaço de mídia que poderia faturar fica vazio. | E9: Qual foi a última coisa no seu shopping que fez alguém parar, tirar o celular do bolso e filmar? | F9: Transformar o shopping em palco: experiências que geram visita, fotos, redes sociais e receita de mídia. História: As grandes capitais têm seus pontos de LED que viram cartão-postal. Uma tela anamórfica 3D na praça de eventos faz o shopping aparecer nas redes de milhares de pessoas, de graça. | G9: Receita: Mall media digital vendido para lojistas e marcas nacionais; ativações e eventos com patrocínio. Experiência: Experiências instagramáveis, datas comemorativas e eventos que aumentam fluxo e permanência. Operação: Sinalização e wayfinding digitais, comunicação com lojistas e campanhas atualizadas em minutos. | H9: Shopping sem experiência é só um estacionamento com lojas. | I9: Painéis de praça de eventos, LED anamórfico/3D, empenas e fachadas, totens, mall media em rede. KPIs: Fluxo de visitantes, permanência, receita de mall media, menções nas redes. | K9: Aprovação por financeiro; Concorrência; Percepção de valor | L9: Vamos criar o ponto do seu shopping que todo mundo quer filmar? Próximo passo: Proposta de experiência-âncora para a próxima data forte (Natal, Dia das Mães) + plano de mall media. | M9: =COUNTIF(Ideias!$C:$C,A9) -> 0
A10: Concessionárias de Veículos | B10: Dono do grupo, Gerente Geral, Gerente de Marketing da concessionária | C10: Status · Experiência · Branding | D10: Showroom com carros parados e banners genéricos da montadora. O cliente chega já pesquisado na internet e o showroom não acrescenta emoção. Custo de esperar: Venda de alto ticket é emoção. Showroom frio perde o cliente para a loja que faz ele imaginar o carro na estrada. | E10: Seu cliente já viu o carro no site. O que o seu showroom mostra que o site não mostra? | F10: Levar a estrada para dentro do showroom: fazer o cliente sentir o carro antes do test-drive. História: Lançamento: luzes apagam, o painel atrás do carro mostra a serra, a chuva, a família viajando, e o carro real está ali na frente. Isso é cenografia que vende. | G10: Receita: Mais conversão no showroom, eventos de lançamento que geram leads e cofinanciamento de ações com a montadora. Experiência: Showroom premium alinhado ao padrão global das marcas; experiência que justifica o preço. Operação: Conteúdo da montadora, condições e estoque atualizados em tempo real; fachada que comunica ofertas para a avenida. | H10: Carro se compra com o coração e se justifica com a razão. O painel fala com os dois. | I10: Painel de fundo de showroom, LED de fachada, totens de ofertas, painel para eventos e lançamentos (venda ou locação). KPIs: Conversão de visita em venda, leads de eventos, tempo de permanência no showroom. | K10: Preço; Momento financeiro; Gestão de conteúdo | L10: Vamos fazer o seu próximo lançamento ser lembrado? Próximo passo: Demonstração no showroom LedWave com conteúdo da marca do cliente. | M10: =COUNTIF(Ideias!$C:$C,A10) -> 0
A11: Construtoras e Stands de Vendas | B11: Diretor de Incorporação, Diretor de Marketing, Gerente de Vendas imobiliárias | C11: Status · Retrofit / arquitetura · Experiência | D11: Vender na planta é vender algo que não existe. Maquete e perspectivas impressas não fazem o cliente se imaginar morando lá. Custo de esperar: Cada visita ao stand que sai sem emoção é uma unidade que vai para o concorrente. Ciclo de venda mais longo é custo financeiro. | E11: Seu cliente está comprando um sonho que ainda é um terreno. Como ele enxerga esse sonho hoje no seu stand? | F11: Fazer o cliente viver o empreendimento antes de ele existir. História: Visitante entra no stand, o painel abre a vista do 20º andar ao pôr do sol, depois a área de lazer com as crianças na piscina. Ele não vê uma planta; ele vê a vida dele. | G11: Receita: Vendas mais rápidas no lançamento; o painel acompanha os próximos empreendimentos (reaproveitamento entre stands). Experiência: Stand com padrão de alto luxo, coerente com o ticket do imóvel; tapume digital que vira mídia na obra. Operação: Atualização de tabela, unidades disponíveis e condições em tempo real; locação para stands temporários. | H11: Ninguém compra metro quadrado. Compra o futuro que cabe nele. | I11: Painel imersivo no stand, LED em tapume de obra, fachada do stand, locação para lançamentos. KPIs: Velocidade de vendas (unidades/mês), conversão de visita em proposta, custo de stand por unidade vendida. | K11: Forma de pagamento; Fabricação de estrutura metálica; Preço | L11: Vamos fazer o seu próximo lançamento ser visto antes de ser construído? Próximo passo: Apresentar conceito imersivo para o próximo lançamento + comparativo compra x locação. | M11: =COUNTIF(Ideias!$C:$C,A11) -> 0
A12: Franquias e Redes | B12: Franqueador (CEO, Diretor de Expansão, Marketing), franqueados master | C12: Branding · Eficiência operacional · Trade | D12: Garantir que a marca seja a mesma em 50, 200, 1.000 lojas. Campanhas chegam atrasadas, impressos são aplicados errado, cada franqueado faz de um jeito. Custo de esperar: Marca inconsistente perde valor e o franqueado perde venda; cada campanha impressa é custo multiplicado pelo número de lojas. | E12: Se hoje você lança uma campanha nacional às 9h, a que horas ela está na última loja da rede? | F12: Dar ao franqueador o controle da marca em todas as lojas e ao franqueado uma loja que vende mais. História: Rede com campanha de Dia dos Pais: com impresso, chega em semanas e cada loja aplica de um jeito; com LED em rede, um clique na central e todas as lojas do Brasil estão iguais no mesmo minuto. | G12: Receita: Campanhas no tempo certo vendem mais; padronização aumenta o ticket e a percepção de valor da marca. Experiência: Experiência idêntica em qualquer cidade, fator de atração para novos franqueados. Operação: Gestão centralizada de conteúdo, kit padrão de tela para novas unidades, fim da logística de impressos. | H12: Uma marca, mil lojas, um clique. | I12: Kit de LED padrão por formato de loja, menu boards, vitrine digital, gestão de conteúdo em rede. KPIs: Tempo de rollout de campanha, aderência ao padrão, vendas por loja, custo de comunicação por unidade. | K12: Forma de pagamento; Crédito; Gestão de conteúdo | L12: Vamos colocar o padrão LedWave no seu kit de abertura de loja? Próximo passo: Projeto de kit padrão para o modelo de loja do cliente + piloto em lojas próprias. | M12: =COUNTIF(Ideias!$C:$C,A12) -> 0
A13: Bares, Restaurantes e Food Service | B13: Proprietário, sócio-operador, Diretor de Marketing de rede de alimentação | C13: Entretenimento · Experiência · Eficiência operacional | D13: Cardápio impresso desatualizado, preços que mudam com o custo dos insumos e pouca visibilidade dos pratos de maior margem. Custo de esperar: Cada reimpressão de cardápio é custo; cada cliente que pede o prato de menor margem por falta de destaque é lucro perdido. | E13: Qual é o prato com a melhor margem da sua casa? E ele é o que mais aparece para o cliente? | F13: Fazer o cardápio vender: mostrar o prato certo, na hora certa, com a cara de dar água na boca. História: Happy hour: às 17h o menu board muda sozinho para chopp e petiscos; no almoço, o executivo; à noite, o prato assinatura em vídeo. O cardápio trabalha por turno. | G13: Receita: Destaque dos itens de maior margem, combos e upsell; transmissão de jogos e eventos que enchem a casa. Experiência: Ambiente moderno e instagramável; fachada que chama de longe. Operação: Preço atualizado em minutos, sem reimpressão; programação automática por horário. | H13: Prato que não é visto não é pedido. | I13: Menu boards em LED, painel de fachada, telão para jogos e eventos, painéis decorativos. KPIs: Ticket médio, vendas dos itens destacados, economia com impressão, ocupação em dias de evento. | K13: Preço; Fobia digital; Momento financeiro | L13: Vamos colocar o seu cardápio para vender sozinho? Próximo passo: Simulação do menu board com o cardápio real do cliente. | M13: =COUNTIF(Ideias!$C:$C,A13) -> 0
A14: Igrejas e Centros Religiosos | B14: Pastor/Padre responsável, Conselho/Diretoria, Ministério de Mídia e Louvor | C14: Insumo de trabalho · Experiência · Entretenimento | D14: A mensagem precisa alcançar todos, do primeiro ao último banco e também quem assiste online. Projetores perdem brilho, letra de louvor não se lê, e a transmissão fica pobre. Custo de esperar: Quem não enxerga e não escuta se desconecta. A nova geração está acostumada com telas de alta qualidade e compara. | E14: Quem está no último banco da sua igreja vê o culto com a mesma clareza de quem está na primeira fila? | F14: Levar a mensagem com clareza a cada pessoa, presente ou online, e criar um ambiente de acolhimento e celebração. História: O mesmo culto com projetor (imagem lavada, luz acesa atrapalhando) e com painel de LED (letra nítida, imagem do pregador ampliada, transmissão bonita). A mensagem é a mesma; o alcance muda. | G14: Receita: Mais engajamento e permanência dos membros, eventos e conferências que atraem visitantes, transmissão de melhor qualidade que amplia o alcance. Experiência: Louvor com letras legíveis, imagem ampliada do pregador, cenografia para datas especiais (Páscoa, Natal, conferências). Operação: Não depende de escurecer o templo, sem troca de lâmpadas de projetor, vida útil longa, suporte técnico. | H14: A mensagem merece ser vista por todos, do altar ao último banco. | I14: Painel de LED de palco (indoor, pixel pitch conforme distância), painéis laterais, telão para eventos (locação), fachada para comunicação com a comunidade. KPIs: Legibilidade/visibilidade em todos os assentos, audiência online, participação em eventos. | K14: Forma de pagamento; Insegurança técnica; Aprovação por financeiro | L14: Vamos levar a sua mensagem com a clareza que ela merece? Próximo passo: Visita técnica ao templo para medir distâncias e simular o painel ideal. | M14: =COUNTIF(Ideias!$C:$C,A14) -> 0
A15: Hotéis, Parques, Clubes e Piscinas | B15: Gerente Geral, Diretor Comercial/Eventos, Presidente de clube, Diretor de Lazer | C15: Entretenimento · Experiência · Status | D15: Disputa por eventos corporativos e sociais, áreas de lazer sem experiência diferenciada e comunicação com hóspedes/associados dispersa. Custo de esperar: O evento corporativo vai para o concorrente que tem estrutura pronta; o associado/hóspede não percebe o valor do que paga. | E15: Quando uma empresa escolhe onde fazer a convenção anual, o que faz ela escolher o seu espaço e não o do concorrente? | F15: Transformar espaços em experiências: eventos mais fortes, lazer memorável e comunicação que encanta. História: Piscina com painel à noite: cinema ao ar livre, jogo da Seleção, festa temática. O mesmo espaço vira três produtos diferentes na mesma semana. | G15: Receita: Locação de salões com estrutura de LED inclusa (valor agregado ao pacote), eventos temáticos que geram receita extra, patrocínio. Experiência: Experiências únicas na área de lazer, wayfinding e boas-vindas personalizadas. Operação: Estrutura fixa elimina locação a cada evento; painéis outdoor resistentes para áreas abertas. | H15: Espaço sem experiência é só metro quadrado. | I15: Painéis fixos para salões de eventos, LED outdoor para piscinas e áreas abertas, totens de comunicação, telões para jogos. KPIs: Taxa de ocupação de salões, receita por evento, satisfação de hóspedes/associados, economia com locação. | J15: Beto Carrero World; Rosewood; Animalia | K15: Consumo de energia; Manutenção; Momento financeiro | L15: Vamos transformar o seu espaço no lugar que todo mundo quer reservar? Próximo passo: Levantamento de eventos dos últimos 12 meses para cálculo de compra x locação. | M15: =COUNTIF(Ideias!$C:$C,A15) -> 0
A16: Eventos, Agências e Produtoras | B16: Sócio da produtora/agência, Diretor de Produção, Diretor de Criação | C16: Insumo de trabalho · Entretenimento · Experiência | D16: Prazo curto, cliente exigente e fornecedor que falha na montagem. Um painel com falha ao vivo queima a reputação da agência. Custo de esperar: Um evento que dá errado custa o cliente inteiro, não só aquele job. | E16: Qual foi o pior momento técnico que você já viveu ao vivo num evento? Nosso trabalho é que ele nunca se repita. | F16: Ser o parceiro que garante que a ideia da agência apareça ao vivo exatamente como foi criada. História: Circuito LedWave da Copa: ativações que movimentaram o mercado e elevaram a demanda por painéis de LED em 50%. Escala, prazo e operação ao vivo são o nosso dia a dia. | G16: Receita: Estoque, logística e equipe técnica próprios permitem atender jobs grandes e simultâneos, com margem previsível para a agência. Experiência: Formatos criativos (curvos, 3D, piso, transparente) que fazem a ativação ser lembrada. Operação: Montagem, operação e backup técnico com equipe LedWave; presença em várias praças (Goiânia, SP, Brasília, EUA). | H16: Ao vivo não tem segunda chance. Tem LedWave. | I16: Locação de painéis indoor/outdoor, formatos especiais, operação técnica e conteúdo. KPIs: Uptime ao vivo, prazo de montagem cumprido, recompra de clientes da agência. | K16: Preço; SLA; Concorrência | L16: Qual é o próximo grande job? Vamos montar juntos? Próximo passo: Cadastro como parceiro preferencial + tabela de locação para o próximo trimestre. | M16: =COUNTIF(Ideias!$C:$C,A16) -> 0
A17: Corporativo (Comunicação Interna e Recepções) | B17: Diretor de RH/Comunicação Interna, Facilities, CEO, Marketing institucional | C17: Branding · Status · Retrofit / arquitetura | D17: Comunicação interna que ninguém lê (e-mail, mural, intranet). Recepção e auditório que não refletem o tamanho e a inovação da empresa. Custo de esperar: Colaborador desinformado é colaborador desengajado; visitante que entra numa recepção comum não sente a grandeza da empresa. | E17: Se um investidor entrasse hoje na sua recepção, em quantos segundos ele entenderia quem vocês são? | F17: Fazer a cultura da empresa ser vista e vivida todos os dias, por quem trabalha e por quem visita. História: Fábrica com 2.000 colaboradores: metas de segurança, aniversariantes e resultados no painel do refeitório. A informação chega a quem não tem e-mail corporativo. | G17: Receita: Engajamento e produtividade, redução de acidentes com comunicação de segurança, impacto em visitantes e clientes. Experiência: Recepção e auditório com padrão de empresa global; eventos internos e convenções com estrutura própria. Operação: Gestão centralizada de mensagens para várias unidades; substitui murais e impressos. | H17: Cultura que não se vê não se vive. | I17: Painel de recepção, auditório e sala de convenção, painéis em refeitórios/fábricas, videowall de comando. KPIs: Alcance da comunicação interna, engajamento em pesquisas de clima, indicadores de segurança. | K17: Aprovação por financeiro; Gestão de conteúdo; Percepção de valor | L17: Vamos fazer a sua empresa contar a própria história todos os dias? Próximo passo: Diagnóstico de pontos de comunicação da empresa + proposta em fases. | M17: =COUNTIF(Ideias!$C:$C,A17) -> 0
A18: Educação (Escolas, Faculdades e Universidades) | B18: Mantenedor, Diretor Geral, Diretor de Marketing/Captação, Coordenador de TI | C18: Insumo de trabalho · Experiência · Status | D18: Concorrência forte na captação de alunos, pais que comparam infraestrutura e comunicação com alunos que não chega. Custo de esperar: A família escolhe a escola em uma visita. Infraestrutura que parece antiga perde matrícula. | E18: Na visita de um pai à sua escola, o que mostra a ele que o filho vai estudar no futuro e não no passado? | F18: Mostrar na prática que a instituição prepara para o futuro e informa a comunidade escolar com eficiência. História: Auditório com painel de LED: formatura, feira de ciências, palestra e transmissão para a família que mora em outra cidade. Um investimento, dezenas de momentos que a família não esquece. | G18: Receita: Captação e retenção de alunos, eventos e formaturas com estrutura própria, locação do auditório para terceiros. Experiência: Ambiente moderno, ensino com conteúdo visual de impacto, eventos memoráveis. Operação: Comunicação de avisos, horários e campanhas em todo o campus; substitui murais. | H18: Escola que mostra o futuro forma para o futuro. | I18: Painel de auditório, LED de fachada e pátio, totens informativos, painéis para ginásio. KPIs: Conversão de visitas em matrícula, uso do auditório, alcance de comunicados. | J18: Museu do Amanhã | K18: Momento financeiro; Forma de pagamento; Fobia digital | L18: Vamos fazer a próxima visita de pais terminar em matrícula? Próximo passo: Visita técnica ao auditório/pátio + simulação de payback por matrícula. | M18: =COUNTIF(Ideias!$C:$C,A18) -> 0
A19: Saúde (Hospitais, Clínicas e Laboratórios) | B19: Diretor Administrativo, Diretor de Marketing, Gerente de Hotelaria Hospitalar | C19: Eficiência operacional · Experiência · Branding | D19: Sala de espera ansiosa, informação desencontrada e marca que precisa transmitir confiança e tecnologia. Custo de esperar: Paciente ansioso tem percepção pior do atendimento; percepção ruim vira avaliação negativa e perda de convênio/particular. | E19: Quanto tempo o seu paciente espera, e o que ele sente nesse tempo? | F19: Acolher o paciente com informação clara, reduzir a ansiedade da espera e mostrar a tecnologia que existe por trás do cuidado. História: Recepção de laboratório: chamada por senha clara, tempo estimado, conteúdo de prevenção e a apresentação dos novos exames. A mesma espera, outra experiência. | G19: Receita: Divulgação de serviços e check-ups (cross-sell), patrocínio de indústria farmacêutica/saúde quando permitido. Experiência: Ambiente acolhedor e moderno, comunicação de prevenção, sinalização clara. Operação: Chamada de pacientes e wayfinding integrados, atualização remota em todas as unidades. | H19: Tecnologia que cuida começa na recepção. | I19: Painéis de recepção e chamada, totens de wayfinding, fachada, painéis em auditório para congressos. KPIs: NPS da recepção, percepção de tempo de espera, vendas de check-ups divulgados. | K19: Insegurança técnica; Aprovação por financeiro; Consumo de energia | L19: Vamos transformar a espera do seu paciente em cuidado? Próximo passo: Diagnóstico de jornada do paciente na unidade principal. | M19: =COUNTIF(Ideias!$C:$C,A19) -> 0
A20: Arenas, Estádios, Academias e Esportes | B20: Presidente/Diretor de clube, Gestor de arena, Dono de rede de academias, Marketing esportivo | C20: Entretenimento · Mídia · Experiência | D20: Patrocinador quer exposição medida, torcedor quer espetáculo e academia precisa reter aluno num mercado de preço. Custo de esperar: Placa estática vende uma marca por vez; painel digital vende várias. Quem não digitaliza deixa receita de patrocínio na mesa. | E20: Quantos patrocinadores cabem em uma placa estática? E em um painel de LED? | F20: Transformar cada jogo, aula e treino em espetáculo e cada metro de placa em receita de patrocínio. História: Placa de campo digital: no mesmo jogo, 20 patrocinadores em rotação, replay, gol em animação e a torcida filmando. O espaço é o mesmo; a receita multiplica. | G20: Receita: Mais cotas de patrocínio no mesmo espaço, ativações e naming de momentos (gol, intervalo). Experiência: Espetáculo para torcedor e aluno; aulas coletivas imersivas; telão em arena. Operação: Gestão de inserções e comprovação para patrocinadores; painéis resistentes para uso intenso. | H20: Placa estática vende uma marca. LED vende o jogo inteiro. | I20: Placas de campo (perimetrais), telões de arena, painéis para academias e salas de aulas coletivas. KPIs: Número de cotas vendidas, receita de patrocínio, retenção de alunos, público. | K20: Crédito; Manutenção; Fabricação de estrutura metálica | L20: Vamos multiplicar a receita do seu espaço sem aumentar um metro? Próximo passo: Simulação de inventário de patrocínio digital com os números do clube/arena. | M20: =COUNTIF(Ideias!$C:$C,A20) -> 0
A21: Poder Público e Mobiliário Urbano | B21: Secretário (Comunicação, Turismo, Mobilidade), Prefeito, Concessionárias de mobiliário urbano | C21: Mídia · Experiência · Retrofit / arquitetura | D21: Comunicar com o cidadão de forma rápida (alertas, serviços, eventos) e modernizar a cidade com orçamento limitado. Custo de esperar: Comunicação lenta em emergências e cidade que não se valoriza turisticamente. | E21: Em uma emergência na sua cidade, quanto tempo leva para o cidadão na rua receber a informação? | F21: Uma cidade que informa, acolhe e se orgulha: tecnologia a serviço do cidadão. História: Brasília ganhou um ícone: o Boulevard.Live, o maior painel de LED da América Latina. Um painel bem posicionado vira ponto turístico, canal de utilidade pública e mídia. | G21: Receita: Modelos de concessão/PPP em que a mídia comercial custeia o equipamento e o espaço público. Experiência: Valorização turística, eventos públicos, orgulho da cidade. Operação: Comunicação de utilidade pública em tempo real (trânsito, defesa civil, saúde). | H21: Cidade que informa é cidade que cuida. | I21: Mobiliário urbano digital, painéis de utilidade pública, telões para eventos públicos, painéis de turismo. KPIs: Alcance da comunicação pública, receita de concessão, eventos realizados. | J21: Museu do Amanhã | K21: Política local / licenças; Consumo de energia; SLA | L21: Vamos desenhar juntos o modelo que moderniza a cidade sem pesar no orçamento? Próximo passo: Reunião técnica para apoiar termo de referência ou estudo de concessão. | M21: =COUNTIF(Ideias!$C:$C,A21) -> 0

Sheet Mapa de Venda
A1: Mapa de Venda: propósito → diferencial → resultado
A2: Insight do time comercial. Descubra o propósito de compra e conduza a conversa pela linha dele.
A3: Propósito de compra | B3: O que o cliente quer | C3: Pergunta para identificar | D3: Diferenciais que provam | E3: Resultados que entrega | F3: Objeções típicas | G3: Cases | H3: Frase de efeito | I3: Nichos onde aparece
A4: Mídia | B4: Vender espaço na tela para anunciantes e transformar o painel em fonte de receita. | C4: Você pensa em vender espaço na tela para outras marcas? | D4: Veículo de mídia; Software e programática; Joint venture; Modelo comercial | E4: Monetização; aumento de receita; impacto | F4: Política local / licenças; Crédito; SLA | H4: Painel apagado é aluguel perdido. | I4: Postos de Combustível e Conveniência; DOOH e Investidores de Mídia; Shopping Centers; Arenas, Estádios, Academias e Esportes; Poder Público e Mobiliário Urbano
A5: Eficiência operacional | B5: Trocar impressos, reduzir retrabalho e atualizar a comunicação de várias unidades de um só lugar. | C5: Quanto tempo e dinheiro a sua equipe gasta hoje para trocar a comunicação? | D5: Software e programática; Solução 360; Capilaridade de atendimento | E5: Eficiência ops; economia; dinamismo; facilidade técnica | F5: Fobia digital; Gestão de conteúdo; Percepção de valor | G5: Nordestão | H5: Uma marca, mil lojas, um clique. | I5: Supermercados, Atacarejos e Home Centers; Postos de Combustível e Conveniência; Franquias e Redes; Bares, Restaurantes e Food Service; Saúde (Hospitais, Clínicas e Laboratórios)
A6: Branding | B6: Fortalecer a marca e ser lembrado: a tela como assinatura visual da empresa. | C6: O que você quer que as pessoas lembrem da sua marca quando passam por aqui? | D6: Customização; Liderança; Prova social | E6: Empoderamento da mensagem; modernidade; diferencial competitivo | F6: Preço; Percepção de valor | H6: Toda empresa comunica. Poucas encantam. | I6: Varejo de Moda e Vitrines; Farmácias e Drogarias; Postos de Combustível e Conveniência; Concessionárias de Veículos; Franquias e Redes; Corporativo (Comunicação Interna e Recepções); Saúde (Hospitais, Clínicas e Laboratórios)
A7: Retrofit / arquitetura | B7: Modernizar fachadas, halls e prédios, integrando o LED ao projeto arquitetônico. | C7: Existe uma reforma ou um projeto de arquitetura em andamento? | D7: Customização; Única fábrica; Certificações; Garantias | E7: Beleza; modernidade; longevidade; qualidade | F7: Fabricação de estrutura metálica; Política local / licenças; Consumo de energia | G7: Rosewood; Museu do Amanhã | H7: O prédio vira mensagem. | I7: DOOH e Investidores de Mídia; Construtoras e Stands de Vendas; Corporativo (Comunicação Interna e Recepções); Poder Público e Mobiliário Urbano
A8: Retail media | B8: Fazer do ponto de venda um canal de mídia vendido para a indústria. | C8: A indústria já paga por exposição nas suas lojas? Ela pede comprovação? | D8: Software e programática; Modelo comercial; Joint venture | E8: Monetização; aumento do fluxo no PDV; aumento de receita | F8: Gestão de conteúdo; Aprovação por financeiro; Cenário mercadológico | G8: Nordestão | H8: Sua loja já tem audiência. Falta transformar audiência em receita. | I8: Supermercados, Atacarejos e Home Centers; Farmácias e Drogarias
A9: Trade | B9: Executar e comprovar as ações de trade marketing no PDV, no tempo certo. | C9: Como as campanhas de trade chegam às lojas hoje, e como você comprova a execução? | D9: Software e programática; Capilaridade de atendimento; Solução 360 | E9: Aumento do fluxo no PDV; dinamismo; eficiência ops | F9: Gestão de conteúdo; Política comercial | G9: Nordestão | H9: Campanha que chega atrasada não vende. | I9: Varejo de Moda e Vitrines; Supermercados, Atacarejos e Home Centers; Farmácias e Drogarias; Franquias e Redes
A10: Insumo de trabalho | B10: Usar o painel como ferramenta do dia a dia: palco, culto, aula, transmissão, evento. | C10: Com que frequência você precisa de tela para trabalhar (eventos, cultos, aulas, transmissões)? | D10: Locação / venda; Estoque; Acervo; Garantias | E10: Disponibilidade física; equipe técnica; garantia; facilidade técnica | F10: Manutenção; SLA; Insegurança técnica | H10: Ao vivo não tem segunda chance. | I10: Igrejas e Centros Religiosos; Eventos, Agências e Produtoras; Educação (Escolas, Faculdades e Universidades)
A11: Experiência | B11: Encantar o cliente, o visitante ou o colaborador e fazer o espaço ser lembrado. | C11: O que você quer que as pessoas sintam quando entram aqui? | D11: Customização; Solução 360; Prova social | E11: Impacto; fidelização; realização; inovação | F11: Preço; Percepção de valor | G11: Animalia; Rosewood; Beto Carrero World; Museu do Amanhã | H11: Espaço sem experiência é só metro quadrado. | I11: Varejo de Moda e Vitrines; Shopping Centers; Concessionárias de Veículos; Construtoras e Stands de Vendas; Bares, Restaurantes e Food Service; Igrejas e Centros Religiosos; Hotéis, Parques, Clubes e Piscinas; Eventos, Agências e Produtoras; Educação (Escolas, Faculdades e Universidades); Saúde (Hospitais, Clínicas e Laboratórios); Arenas, Estádios, Academias e Esportes; Poder Público e Mobiliário Urbano
A12: Entretenimento | B12: Atrair e reter público com conteúdo, shows, jogos e atrações. | C12: Que tipo de atração faria o seu público voltar mais vezes? | D12: Customização; Acervo; Locação / venda | E12: Fidelização; impacto; aumento de receita; exclusividade | F12: Consumo de energia; Manutenção; Momento financeiro | G12: Animalia; Beto Carrero World | H12: Quem encanta, faz voltar. | I12: Shopping Centers; Bares, Restaurantes e Food Service; Igrejas e Centros Religiosos; Hotéis, Parques, Clubes e Piscinas; Eventos, Agências e Produtoras; Arenas, Estádios, Academias e Esportes
A13: Status | B13: Ter o painel mais impressionante, a referência da cidade ou do setor. | C13: Que projeto de LED você viu e pensou: eu quero isso para nós? | D13: Liderança; Premiações; Pioneira; Customização | E13: Exclusividade; diferencial competitivo; inovação; realização | F13: Preço; Concorrência | G13: Rosewood | H13: Seja a referência que os outros vão copiar. | I13: DOOH e Investidores de Mídia; Concessionárias de Veículos; Construtoras e Stands de Vendas; Hotéis, Parques, Clubes e Piscinas; Corporativo (Comunicação Interna e Recepções); Educação (Escolas, Faculdades e Universidades)

Sheet Diferenciais
A1: Diferenciais da LedWave
A2: Use 3 a 5 por apresentação, escolhidos pelo propósito de compra. 'Confirmar' = validar com o comercial antes de usar com cliente.
A3: Diferencial | B3: Como falar | C3: Prova / o que levar | D3: Status | E3: Observação
A4: Joint venture | B4: Somamos forças com parceiros de mídia para entregar não só a tela, mas o negócio de mídia por trás dela. | C4: Nome e escopo da joint venture (ex.: WeOOH?) | D4: Confirmar
A5: Modelo comercial | B5: Montamos o modelo que cabe no seu negócio: compra, locação, mídia compartilhada ou combinações. | C5: Tabela de modelos comerciais | D5: Confirmar
A6: Locação / venda | B6: Você escolhe: comprar, alugar ou começar alugando e depois comprar. | C6: Comparativo compra x locação | D6: OK
A7: Capilaridade de atendimento | B7: Atendemos o Brasil inteiro a partir de Goiânia, São Paulo e Brasília, e os EUA por Orlando. | C7: Mapa de atendimento e equipes | D7: OK
A8: Estoque | B8: Temos estoque próprio: menos espera entre a assinatura e a tela acesa. | C8: Prazo médio de entrega | D8: Confirmar prazos
A9: Acervo | B9: Um acervo amplo de modelos e formatos para cada aplicação: indoor, outdoor, curvo, transparente, piso. | C9: Catálogo de produtos / acervo de locação | D9: Confirmar significado
A10: Tempo de vida | B10: Mais de 15 anos de mercado e painéis feitos para durar. | C10: Ano de fundação + vida útil dos painéis | D10: Confirmar significado
A11: Know-how | B11: Mais de 15 anos fabricando, instalando e operando painéis de LED: sabemos o que funciona em cada tipo de espaço, do PDV ao maior painel da América Latina. | C11: Histórico de projetos + Boulevard.Live | D11: OK
A12: Prova social | B12: Marcas como Nordestão, Rosewood, Beto Carrero World e Museu do Amanhã escolheram a LedWave. | C12: Cases e depoimentos | D12: OK
A13: Única fábrica | B13: Fabricamos no Brasil, com linha de produção própria em Goiânia. | C13: Confirmar se é a única fábrica do Brasil antes de dizer 'única' | D13: Confirmar
A14: Certificações | B14: Produtos certificados e processos dentro das normas. | C14: Lista de certificações | D14: Confirmar lista
A15: Pioneira | B15: Fomos pioneiros em trazer a fabricação de painéis de LED para o Brasil. | C15: Histórico 2010/2011 | D15: Confirmar
... A22: Premiações | B22: Quatro anos seguidos no ranking Exame das empresas que mais crescem. | C22: Ranking Exame + outros prêmios | D22: Confirmar outros prêmios

Sheet Objeções
A1: Objeções: resposta curta + prova
A2: Método: ouvir até o fim → acolher → explorar ('além disso, tem mais algo?') → responder com prova → confirmar.
A3: Categoria | B3: Objeção | C3: Resposta | D3: Leve / prova | E3: Funcionou? | F3: Variação que funcionou
A4: Percepção | B4: Fobia digital | C4: Atualizar a tela é tão simples quanto postar no Instagram. Treinamos a sua equipe, e a LedWave pode cuidar do conteúdo para você. | D4: Demonstração do software no celular
A5: Financeira | B5: Preço | C5: Vamos comparar o custo total: impressos, locações e vendas perdidas de um ano contra o investimento no painel, que fica com você por muitos anos. | D5: Planilha de custo total / payback
A6: Técnica | B6: Qualidade | C6: Venha ver de perto: fabricamos no Brasil, com garantia e suporte próprio. E marcas como Rosewood e Museu do Amanhã aprovaram essa qualidade. | D6: Visita ao showroom + cases
A7: Operacional | B7: Gestão de conteúdo | C7: Você não fica sozinho: entregamos o software, o treinamento e, se quiser, a produção e a programação do conteúdo. | D7: Pacote de conteúdo
A8: Técnica | B8: Fabricação de estrutura metálica | C8: A estrutura faz parte do projeto: dimensionamos, fabricamos e instalamos com responsabilidade técnica, sem você precisar de outro fornecedor. | D8: Projeto estrutural + ART
A9: Operacional | B9: Manutenção | C9: Temos equipe técnica e estoque de peças próprios, e oferecemos contrato de manutenção preventiva. | D9: Contrato de manutenção
A10: Operacional | B10: SLA | C10: O prazo de atendimento fica escrito no contrato. [Preencher prazos oficiais de SLA] | D10: Contrato com SLA
A11: Financeira | B11: Política comercial | C11: Explique as condições com transparência e leve a proposta já dentro da alçada aprovada, com alternativas. | D11: Tabela de condições
A12: Regulatória | B12: Política local / licenças | C12: Apoiamos o licenciamento: projeto técnico, documentação e orientação sobre as regras da sua cidade. | D12: Checklist de licenciamento
A13: Financeira | B13: Forma de pagamento | C13: Temos opções: à vista, parcelado, financiamento e locação. Montamos a que cabe no seu fluxo de caixa. | D13: Simulação de pagamento
A14: Financeira | B14: Política de pagamento / locação / WDC | C14: [Confirmar o que é WDC] Apresente as regras de pagamento e locação de forma simples, com um exemplo numérico. | D14: Tabela de condições
A15: Financeira | B15: Momento financeiro | C15: Podemos começar por um piloto ou pela locação, que vira despesa mensal em vez de investimento, e crescer por fases. | D15: Proposta em fases
... A25: Decisão | B25: Preciso falar com meu sócio / diretoria. | C25: Ótimo. Posso preparar um resumo executivo de uma página e, se fizer sentido, apresento junto com você. | D25: Resumo executivo de 1 página
A26: Nicho: Varejo de Moda e Vitrines | B26: Painel de LED é caro para uma loja só. | C26: Compare com o custo de 12 meses de impressos, instalação e mídia local. O painel substitui esses custos e ainda fica com você. Podemos montar a conta juntos agora.
A27: Nicho: Supermercados, Atacarejos e Home Centers | B27: Não tenho equipe para gerenciar conteúdo e vender mídia. | C27: Por isso a LedWave entrega a solução completa: tela, gestão de conteúdo e modelo de negócio. Você cuida da loja, nós ajudamos a operar a mídia.
A28: Nicho: Farmácias e Drogarias | B28: A fachada da farmácia tem regras de padronização da rede/franquia. | C28: Trabalhamos com o manual da marca: o painel vira parte da identidade, não uma exceção a ela. Levamos a proposta pronta para aprovação do franqueador.
A29: Nicho: Postos de Combustível e Conveniência | B29: Meu cliente só olha preço. | C29: Exatamente: e o painel mostra o preço melhor, mais longe e mais rápido. O que vem depois do preço (café, lavagem, mídia) é margem extra que hoje você não captura.
A30: Nicho: DOOH e Investidores de Mídia | B30: O payback é longo e o risco é alto. | C30: Por isso o projeto começa pelo ponto, não pelo painel: fluxo, visibilidade, licenciamento e plano comercial. Com fabricante que também opera mídia, o risco técnico cai.
A31: Nicho: Shopping Centers | B31: Já temos TVs espalhadas pelo mall. | C31: TV comunica; LED de grande formato encanta. Escala, brilho e formato livre criam momentos que uma TV não cria, e é isso que vende mídia premium.
A32: Nicho: Concessionárias de Veículos | B32: A montadora define o padrão do showroom. | C32: O painel recebe o conteúdo oficial da montadora e respeita o padrão visual. Podemos apresentar a proposta junto à regional da marca.
A33: Nicho: Construtoras e Stands de Vendas | B33: O stand é temporário, não compensa comprar. | C33: Temos locação e também compra com reaproveitamento: o mesmo painel vai do stand para o próximo lançamento ou para o hall do prédio entregue.
A34: Nicho: Franquias e Redes | B34: O franqueado não vai querer pagar. | C34: Mostramos ao franqueado a conta: economia de impressos + venda adicional. E temos modelos de financiamento e de kit de abertura que diluem o investimento.
A35: Nicho: Bares, Restaurantes e Food Service | B35: Meu restaurante é pequeno para isso. | C35: O painel é dimensionado para o seu espaço. Começamos pelo menu board ou pela fachada, onde o retorno é mais rápido.
A36: Nicho: Igrejas e Centros Religiosos | B36: Precisamos aprovar com a comunidade / fazer campanha de arrecadação. | C36: Preparamos material para a apresentação ao conselho e à comunidade, com simulação do templo, e opções de parcelamento compatíveis com campanhas.
A37: Nicho: Hotéis, Parques, Clubes e Piscinas | B37: Já alugamos telão quando há evento. | C37: Somando as locações de um ano, o painel próprio costuma se pagar rápido, e ainda vira diferencial de venda do seu espaço. Vamos fazer essa conta com os seus números?
... A43: Nicho: Poder Público e Mobiliário Urbano | B43: Precisa passar por licitação. | C43: Temos equipe dedicada a licitações e apoiamos na especificação técnica correta, para que a cidade compre qualidade e não apenas o menor preço.

Sheet Cases
A1: Cases de referência
A2: Preencha desafio, entrega e resultado: é isso que entra nas apresentações. Só use com cliente após autorização.
A3: Case | B3: Nicho | C3: Propósitos de compra | D3: Desafio do cliente | E3: O que a LedWave entregou | F3: Resultado | G3: Autorizado? | H3: Status
A4: Nordestão | B4: Supermercados, Atacarejos e Home Centers | C4: Retail media; Trade; Eficiência operacional | H4: Detalhar
A5: Animalia | B5: Hotéis, Parques, Clubes e Piscinas | C5: Entretenimento; Experiência | H5: Confirmar segmento e detalhar
A6: Rosewood | B6: Hotéis, Parques, Clubes e Piscinas | C6: Status; Experiência; Retrofit / arquitetura | H6: Detalhar
A7: Beto Carrero World | B7: Hotéis, Parques, Clubes e Piscinas | C7: Entretenimento; Experiência | H7: Detalhar
A8: Cestto | B8: [Confirmar segmento] | H8: Confirmar
A9: Museu do Amanhã | B9: Poder Público e Mobiliário Urbano | C9: Experiência; Retrofit / arquitetura | H9: Detalhar

Sheet Descoberta
A1: Descoberta e orçamento por nicho
A2: Perguntas SPIN (faça poucas de Situação, mais de Implicação) e o que levantar para orçar certo.
A3: Nicho | B3: S · Situação | C3: P · Problema | D3: I · Implicação | E3: N · Necessidade | F3: Dados para orçar | G3: Armadilha de orçamento
A4: Varejo de Moda e Vitrines | B4: Quantas lojas vocês têm e quantas trocas de coleção/campanha fazem por ano? Como a vitrine é produzida hoje? | C4: O que mais atrasa ou encarece uma troca de vitrine? Já perderam uma promoção por não dar tempo de imprimir? | D4: Se a vitrine fica a mesma por semanas, o que acontece com o fluxo de quem passa todo dia na frente? Quanto isso pesa na venda da coleção nova? | E4: Se você pudesse trocar a vitrine de todas as lojas pelo celular, em minutos, o que faria diferente na próxima campanha? | F4: Medidas da vitrine; vidro (painel atrás do vidro = alto brilho ou LED transparente); incidência de sol; horário de funcionamento; distância da calçada; nº de lojas. Qualificação: Quem aprova (marketing ou dono)? Orçamento por loja ou para a rede? Data da próxima coleção? | G4: Orçar brilho de indoor para vitrine com sol direto; esquecer o calendário de coleções como prazo.
A5: Supermercados, Atacarejos e Home Centers | B5: Quantas lojas e checkouts? Como as ofertas são comunicadas hoje? A indústria investe em trade nas suas lojas? | C5: Quanto tempo leva para uma oferta sair do comercial e chegar à gôndola? O fornecedor pede comprovação de exposição? | D5: Quanto de verba de trade vira papel que ninguém mede? Quanto você deixa de faturar por não vender mídia dentro da loja? | E5: Se as telas fossem pagas pela indústria e ainda gerassem receita, quantas lojas você colocaria no piloto? | F5: Nº de lojas e checkouts; pontos (entrada, gôndola, checkout, fachada); infraestrutura de rede/energia; integração com preços. Qualificação: Trade/marketing ou operações decide? Indústria vai cofinanciar? Piloto em quantas lojas? | G5: Orçar só hardware sem modelo de retail media e gestão de conteúdo.
A6: Farmácias e Drogarias | B6: Quantas lojas, e quantas abrem por ano? Como funciona a parceria com a indústria hoje? | C6: Como vocês se diferenciam das farmácias concorrentes na mesma rua? Campanhas sazonais chegam a tempo em todas as lojas? | D6: Se o cliente escolhe a farmácia mais visível, quanto fluxo vocês perdem por ter fachada igual às outras? E quanto a indústria investiria se tivesse onde? | E6: Uma rede de telas que se paga com a indústria e destaca a sua fachada ajudaria na meta deste ano? | F6: Fachada (medidas, manual da marca); áreas internas; nº de lojas e aberturas; regras do franqueador. Qualificação: Franqueador aprova? Indústria cofinancia? Meta de rollout? | G6: Ignorar manual de marca e aprovação do franqueador.
A7: Postos de Combustível e Conveniência | B7: Quantos postos, qual o fluxo diário da via, qual o peso da conveniência no resultado? | C7: Como o preço é atualizado hoje? A conveniência é vista da pista? Algum anunciante local já procurou vocês? | D7: Quantos motoristas passam reto por não verem o preço ou a oferta a tempo? Quanto vale um ponto a mais de conversão da pista? | E7: Se o mesmo totem mostrasse preço, promoção da conveniência e ainda vendesse mídia, como isso mudaria a margem do posto? | F7: Totem existente (medidas, estrutura); distância e velocidade da via; exposição a sol/chuva (IP65); bandeira e regras da distribuidora. Qualificação: Proprietário decide sozinho? Bandeira exige padrão? Prazo da reforma? | G7: Pixel pitch fino demais (caro e desnecessário para leitura a distância); esquecer aprovação da bandeira.
A8: DOOH e Investidores de Mídia | B8: Quantos pontos opera, em quais praças, com que ocupação média? Quem é seu fornecedor atual? | C8: Quanto tempo de tela apagada teve no último ano? Qual a maior dificuldade: ponto, licenciamento, venda ou manutenção? | D8: Quanto custou em receita cada dia de tela apagada? Quantos pontos bons a concorrência ocupou enquanto você decidia? | E8: Um parceiro que fabrica, mantém e entende de operação de mídia aceleraria o seu plano de expansão? | F8: Ponto (endereço, fluxo, ângulo, distância); estrutura e laudo; licenciamento municipal; energia; horas de operação/dia. Qualificação: Capital próprio ou financiado? Expectativa de payback? Já tem anunciantes? | G8: Orçar o painel sem validar licença e estrutura; subestimar manutenção e uptime.
